<?xml version="1.0" ?>

<robot name="mark" xmlns:xacro="http://www.ros.org/wiki/xacro">

<link name="base_link">

	<inertial name="base_inertia">
		<origin rpy="0 0 0" xyz="0 0 0"/>
    	<mass value="9"/>
    	<inertia ixx="0.000037" ixy="0.000001" ixz="0" iyy="0.000075" iyz="0" izz="0"/>
   	</inertial>

   <collision name="base_collision">
        <origin rpy="0 0 0" xyz="0 0 0.01"/>
    	<geometry>
       		<mesh filename="package://mark_description/mesh/base/base.dae"/> 
     	</geometry>
   </collision>

	<visual name="base_visual">
    	<origin rpy="0 0 0" xyz="0 0 0.01"/>
     	<geometry>
       		<mesh filename="package://mark_description/mesh/base/base.dae"/>
     	</geometry>
    </visual>

<!--   	<collision name="pillers_collision">
    	<origin rpy="0 0 0" xyz="-0.099185 0 -0.05621"/>
     	<geometry>
       		<mesh filename="package://mark_description/mesh/base/pillers.dae"/> 
     	</geometry>
   	</collision>

   	<visual>
        <origin rpy="0 0 0" xyz="-0.099185 0 -0.05621"/>
    	<geometry>
       		<mesh filename="package://mark_description/mesh/base/pillers.dae"/>
     	</geometry>
   	</visual>-->

  	<collision name="caster_base_collision">
     	<origin rpy=" 0 0 0" xyz="0.223 0 -0.09816"/>
     	<geometry>
       		<sphere radius="0.019"/>
     	</geometry>
     	<surface>
       	<friction>
         	<ode>
           		<mu>0</mu>
           		<mu2>0</mu2>
           		<slip1>1.0</slip1>
           		<slip2>1.0</slip2>
         	</ode>
       	</friction>
     	</surface>
   	</collision>

    <collision name="caster_wheel_collision">
    	<origin rpy=" 0 0 0" xyz="0.223 0 -0.075448"/>
    	<geometry>
    		<cylinder length="0.04" radius="0.02"/>
   		</geometry>
   		<surface>
   		<friction>
       		<ode>
       			<mu>0</mu>
       			<mu2>0</mu2>
       			<slip1>1.0</slip1>
       			<slip2>1.0</slip2>
      		</ode>
   		</friction>
	   	</surface>
   	</collision>

    <visual name="caster_base_visual">
    	<origin rpy=" 0 0 0" xyz="0.223 0 -0.075448"/>
     	<geometry>
       		<cylinder length="0.04" radius="0.02"/>
     	</geometry>
   	</visual>

   	<visual name="caster_wheel_visual">
     	<origin rpy=" 0 0 0" xyz="0.223 0 -0.09816"/>
     	<geometry>
       		<sphere radius="0.019"/>
     	</geometry>
   	</visual>

</link>









	 	<link name="pillers_link">



		<collision name="pillers_collision">
				<origin rpy="0 0 0" xyz="-0.099185 0 -0.05621"/>
				<geometry>
					<mesh filename="package://mark_description/mesh/base/pillers.dae"/> 
				</geometry>
			</collision> 

			<visual name="pillers_visual">
				<origin rpy="0 0 0" xyz="0 0 0"/>
				<geometry>
					<mesh filename="package://mark_description/mesh/base/pillers.dae"/>
				</geometry>
				<material name="Yellow"/>
			</visual>
		</link>

		<joint name="pillers_joint" type="fixed">
				<axis xyz="0 1 0"/>
				<parent link="base_link"/>
				<child link="pillers_link"/>
				<origin rpy="0 0 0" xyz="-0.099185 0 -0.05621"/>
			</joint> 








<!--left wheel rim-->

<link name="left_rim_link">

	<inertial>
     	<origin rpy="-1.57075 0 0" xyz="0 0 0"/>
		<mass value="0.85"/>
		<inertia ixx="0.001" ixy="0" ixz="0" iyy="0.001" iyz="0" izz="0.001"/>
	</inertial>

	<visual>
        <origin rpy="-1.57075 0 0" xyz="0 0 0"/>	
		<geometry>
        	<mesh filename="package://mark_description/mesh/wheel/wheel_rim.dae"/>
		</geometry>
	</visual>

	<collision>
		<origin rpy="-1.57075 0 0" xyz="0 0 0"/>
		<geometry>
			<cylinder length="0.02" radius="0.06"/>
		</geometry>
	</collision>
			


</link>
	
	<gazebo reference="left_rim_link">
		<material>Gazebo/Grey</material>
		<mu1>1.0</mu1>
		<mu2>1.0</mu2>
		<kp>1000000.0</kp>
		<kd>100.0</kd>
		<minDepth>0.001</minDepth>
		<maxVel>1.0</maxVel>		
	</gazebo>

	<joint name="left_rim_joint" type="continuous">
		<axis xyz="0 1 0"/>
		<parent link="base_link"/>
		<child link="left_rim_link"/>
    	<origin rpy="0 0 0" xyz="-0.099185 0.23646 -0.059645"/>
	</joint> 

<!--left wheel tire-->
<link name="left_tire_link">
	<visual>
		<origin rpy="-1.57075 0 0 " xyz="0 0 0"/>
		<geometry>
	        <mesh filename="package://mark_description/mesh/wheel/wheel_tire.dae"/>
		</geometry>
	</visual>

	<collision>
		<origin rpy="1.57075 0 0" xyz="0 0 0"/>
		<geometry>
			<cylinder length="0.001" radius="0.001"/>
		</geometry>
	</collision>

	<inertial>
		<origin xyz="0 0 0" rpy="0 0 0"/>
		<mass value="0.001"/>
		<inertia ixx="0.001" ixy="0.0" ixz="0.0" iyy="0.001" 	iyz="0.0" izz="0.001" />
	</inertial>
			
</link>
		
	<gazebo reference="left_tire_link">
		<material>Gazebo/Black</material>
        <mu1>1.0</mu1>
		<mu2>1.0</mu2>
		<kp>1000000.0</kp>
		<kd>100.0</kd>
		<minDepth>0.001</minDepth>
		<maxVel>1.0</maxVel>
	</gazebo>	

	<joint name="left_tire_joint" type="continuous">
		<axis xyz="0 1 0"/>
		<parent link="left_rim_link"/>
		<child link="left_tire_link"/>
		<origin rpy="0 0 0" xyz="0.0 0.0 0.0"/>
	</joint>


<!-- right wheel rim -->

<link name="right_rim_link">
	
	<inertial>
   		<origin rpy="1.57075 0 0" xyz="0 0 0"/>
		<mass value="0.85"/>
		<inertia ixx="0.001" ixy="0" ixz="0" iyy="0.001" iyz="0" izz="0.001"/>
	</inertial>

	<visual>
       	<origin rpy="1.57075 0 0" xyz="0 0 0"/>
		<geometry>
       		<mesh filename="package://mark_description/mesh/wheel/wheel_rim.dae"/>
		</geometry>
	</visual>

	<collision>
       	<origin rpy="1.57075 0 0" xyz="0 0 0"/>
		<geometry>
			<cylinder length="0.02" radius="0.06"/>
		</geometry>
	</collision>

</link>
	
	<gazebo reference="right_rim_link">
		<material>Gazebo/Grey</material>
		<mu1>1.0</mu1>
		<mu2>1.0</mu2>
		<kp>1000000.0</kp>
		<kd>100.0</kd>
		<minDepth>0.001</minDepth>
		<maxVel>1.0</maxVel>		
	</gazebo>

	<joint name="right_rim_joint" type="continuous">
		<axis xyz="0 1 0"/>
		<parent link="base_link"/>
		<child link="right_rim_link"/>
	    <origin rpy="0 0 0" xyz="-0.099185 -0.23646 -0.059645"/>
	</joint> 

<!--right tire link-->

<link name="right_tire_link">
	<visual>
		<origin rpy="1.57075 0 0 " xyz="0 0 0"/>
		<geometry>
	        <mesh filename="package://mark_description/mesh/wheel/wheel_tire.dae"/>
		</geometry>
	</visual>

	<collision>
		<origin rpy="1.57075 0 0" xyz="0 0 0"/>
		<geometry>
			<cylinder length="0.001" radius="0.001"/>
		</geometry>
	</collision>

	<inertial>
		<origin xyz="0 0 0" rpy="0 0 0"/>
		<mass value="0.001"/>
		<inertia ixx="0.001" ixy="0.0" ixz="0.0" iyy="0.001" 	iyz="0.0" izz="0.001" />
	</inertial>
			
</link>
		
	<gazebo reference="caster_tire_link">
		<material>Gazebo/Black</material>
        <mu1>1.0</mu1>
		<mu2>1.0</mu2>
		<kp>1000000.0</kp>
		<kd>100.0</kd>
		<minDepth>0.001</minDepth>
		<maxVel>1.0</maxVel>
	</gazebo>	

	<joint name="right_tire_joint" type="continuous">
		<axis xyz="0 1 0"/>
		<parent link="right_rim_link"/>
		<child link="right_tire_link"/>
		<origin rpy="0 0 0" xyz="0.0 0.0 0.0"/>
	</joint>

	<gazebo>
		<plugin filename="libgazebo_ros_diff_drive.so" name="differential_drive_controller">
			<legacyMode>false</legacyMode>
			<alwaysOn>true</alwaysOn>
			<updateRate>100</updateRate>
			<leftJoint>left_rim_joint</leftJoint>
			<rightJoint>right_rim_joint</rightJoint>
			<wheelSeparation>0.45</wheelSeparation>
			<wheelDiameter>0.12</wheelDiameter>
			<torque>0.5</torque>
			<commandTopic>cmd_vel</commandTopic>
			<odometryTopic>odom</odometryTopic>
			<odometryFrame>odom</odometryFrame>
			<publishWheelTF>true</publishWheelTF>
			<publishWheelJointState>true</publishWheelJointState>
			<robotBaseFrame>base_link</robotBaseFrame>
			<odometrySource>world</odometrySource> 
			<publishTf>1</publishTf>
			<rosDebugLevel>na</rosDebugLevel>
			<publishOdomTF>true</publishOdomTF>
			<wheelAcceleration>0</wheelAcceleration> 
			<wheelTorque>5</wheelTorque>
	</plugin>
	</gazebo>

<!--Ahrs/IMU 

<link name="imu_link">

	<inertial>
		<mass value="0.001"/>
		<origin rpy="0 0 0" xyz="0 0 0"/>
		<inertia ixx="0.0001" ixy="0" ixz="0" iyy="0.0001" iyz="0" izz="0.0001"/>
	</inertial>
			
	<visual>
		<origin rpy="0 0 0" xyz="0 0 0"/>
		<geometry>
			<box size="0.001 0.001 0.001"/>
		</geometry>
	</visual>
			
	<collision>
		<origin rpy="0 0 0" xyz="0 0 0"/>
		<geometry>
			<box size="0.001 0.001 0.001"/>
		</geometry>
	</collision>

</link>
		
	<joint name="imu_joint" type="fixed">
		<axis xyz="1 0 0"/>
		<origin xyz="0 0 0" rpy="0 0 0" />
		<parent link="base_link"/>
		<child link="imu_link"/>
	</joint>

	<gazebo>
		<plugin name="imu_plugin" filename="libgazebo_ros_imu.so">
			<alwaysOn>true</alwaysOn>
							<robotNamespace>gazebo</robotNamespace>     
			<frameName>imu_link</frameName>   
			<bodyName>imu_link</bodyName>
			<topicName>imu</topicName>
			<serviceName>imu_service</serviceName>
			<gaussianNoise>0.0</gaussianNoise>
			<updateRate>10</updateRate> 
		</plugin>
	</gazebo>-->


<!--Lider-

<link name="lider_link">

	<inertial>
		<mass value="1e-5" />
		<origin xyz="0 0 0" rpy="0 0 0"/>
		<inertia ixx="1e-6" ixy="0" ixz="0" iyy="1e-6" iyz="0" izz="1e-6" />
	</inertial>

	<visual>
		<origin xyz="0 0 0" rpy="0 0 0"/>
		<geometry>
			<mesh filename="package://mark_description/mesh/lider/rplider.stl" scale="0.001 0.001 0.001"/>
		</geometry>
		<material name="Black" />
	</visual>

	<collision>
		<origin xyz="0 0 0" rpy="0 0 0"/>
		<geometry>
			<box size="0.1 0.1 0.1"/>
		</geometry>
	</collision>		

</link>
		
	<joint name="lider_joint" type="fixed">
		<axis xyz="0 1 0" />
		<origin xyz="-0.008344 0 0.14993" rpy="0 0 1.57075"/>
		<parent link="base_link"/>
		<child link="lider_link"/>
	</joint>
					
	<gazebo reference="lider_link">
		<material>Gazebo/Black</material>
		<sensor type="gpu_ray" name="head_hokuyo_sensor">
			<pose>0 0 0 0 0 0</pose>
			<visualize>false</visualize>
			<update_rate>40</update_rate>
			<ray>
				<scan>
					<horizontal>
						<samples>720</samples>
						<resolution>1</resolution>
						<min_angle>-3.1416</min_angle>
						<max_angle>3.1416</max_angle>
					</horizontal>
				</scan>
					
				<range>
					<min>0.5</min>
					<max>5.0</max>
					<resolution>0.1</resolution>
				</range>
					
				<noise>
					<type>gaussian</type>
					 Noise parameters based on published spec for Hokuyo laser
					achieving "+-30mm" accuracy at range < 10m.  A mean of 0.0m and
					stddev of 0.01m will put 99.7% of samples within 0.03m of the true
					reading.  
					<mean>0.0</mean>
					<stddev>0.01</stddev>
				</noise>
			</ray>

   			<plugin name="lider_controller" filename="libgazebo_ros_gpu_laser.so">
				<topicName>lider</topicName>
				<frameName>lider_link</frameName>
			</plugin> 
		</sensor>
	</gazebo>
-->
</robot>

