<?xml version="1.0"?>

<robot name="mark" xmlns:xacro="http://ros.org/wiki/xacro">
	<xacro:macro name="mark_wheel" params="prefix joint_x joint_y joint_z joint_roll joint_pitch joint_yaw r parent_link">

		<!-- rim link-->
		<link name="${prefix}_rim_link">

			<inertial>
				<origin rpy="0 0 0" xyz="0 0 0"/>
				<mass value="0.85"/>
				<inertia ixx="0.001" ixy="0" ixz="0" iyy="0.001" iyz="0" izz="0.001"/>
			</inertial>

			<visual>
				<origin rpy="${r} 0 0" xyz="0 0 0"/>	
				<geometry>
					<mesh filename="package://mark_description/mesh/wheel/wheel_rim.dae"/>
				</geometry>
			</visual>

			<collision>
				<origin rpy="${r} 0 0" xyz="0 0 0"/>
				<geometry>
					<cylinder length="0.02" radius="0.06"/>
				</geometry>
			</collision>
		</link>
			
			<gazebo reference="${prefix}_rim_link">
				<material>Gazebo/Red</material>
				<mu1>1.0</mu1>
				<mu2>1.0</mu2>
				<kp>1000000.0</kp>
				<kd>100.0</kd>
				<minDepth>0.001</minDepth>
				<maxVel>1.0</maxVel>		
			</gazebo>

			<joint name="${prefix}_rim_joint" type="continuous">
				<axis xyz="0 1 0"/>
				<parent link="${parent_link}"/>
				<child link="${prefix}_rim_link"/>
				<origin rpy="${joint_roll} ${joint_pitch} ${joint_yaw}" xyz="${joint_x} ${joint_y} ${joint_z}"/>
			</joint> 


		<link name="${prefix}_tire_link">
			<visual>
				<origin rpy="-1.57075 0 0 " xyz="0 0 0"/>
				<geometry>
					<mesh filename="package://mark_description/mesh/wheel/wheel_tire.dae"/>
				</geometry>
				<material name="Black" />
			</visual>

			<collision>
				<origin rpy="1.57075 0 0" xyz="0 0 0"/>
				<geometry>
					<cylinder length="0.001" radius="0.001"/>
				</geometry>
			</collision>

			<inertial>
				<origin xyz="0 0 0" rpy="0 0 0"/>
				<mass value="0.001"/>
				<inertia ixx="0.001" ixy="0.0" ixz="0.0" iyy="0.001" 	iyz="0.0" izz="0.001" />
			</inertial>
					
		</link>
				
			<gazebo reference="${prefix}_tire_link">
				<material>Gazebo/Black</material>
				<mu1>1.0</mu1>
				<mu2>1.0</mu2>
				<kp>1000000.0</kp>
				<kd>100.0</kd>
				<minDepth>0.001</minDepth>
				<maxVel>1.0</maxVel>
			</gazebo>	

			<joint name="${prefix}_tire_joint" type="fixed">
				<axis xyz="0 1 0"/>
				<parent link="${prefix}_rim_link"/>
				<child link="${prefix}_tire_link"/>
				<origin rpy="0 0 0" xyz="0.0 0.0 0.0"/>
			</joint>

	</xacro:macro>
</robot>

